<?xml version="1.0" encoding="utf-8"?>
<robot
  name="ca">
  <link
    name="base_link">
    <inertial>
      <origin
        xyz="0.0023443 0.00028765 0.10232"
        rpy="0 0 0" />
      <mass
        value="60" />
      <inertia
        ixx="1.1836"
        ixy="-4.6065E-15"
        ixz="-2.9443E-15"
        iyy="3.6753"
        iyz="1.0467E-16"
        izz="4.5993" />
    </inertial>
    <visual>
      <origin
        xyz="0 0 0"
        rpy="0 0 0" />
      <geometry>
        <mesh
          filename="package://ca/meshes/base_link.STL" />
      </geometry>
      <material
        name="">
        <color
          rgba="0.79216 0.81961 0.93333 1" />
      </material>
    </visual>
    <collision>
      <origin
        xyz="0 0 0"
        rpy="0 0 0" />
      <geometry>
        <mesh
          filename="package://ca/meshes/base_link.STL" />
      </geometry>
    </collision>
  </link>
  <link
    name="wheel1">
    <inertial>
      <origin
        xyz="0 0.12 0"
        rpy="0 0 0" />
      <mass
        value="5" />
      <inertia
        ixx="0.13237"
        ixy="1.7347E-18"
        ixz="-1.9437E-36"
        iyy="0.13869"
        iyz="2.808E-34"
        izz="0.13237" />
    </inertial>
    <visual>
      <origin
        xyz="0 0 0"
        rpy="0 0 0" />
      <geometry>
        <mesh
          filename="package://ca/meshes/wheel1.STL" />
      </geometry>
      <material
        name="">
        <color
          rgba="0.79216 0.81961 0.93333 1" />
      </material>
    </visual>
    <collision>
      <origin
        xyz="0 0 0"
        rpy="0 0 0" />
      <geometry>
        <mesh
          filename="package://ca/meshes/wheel1.STL" />
      </geometry>
    </collision>
  </link>
  <joint
    name="wheel1j"
    type="continuous">
    <origin
      xyz="0.695 0.4065 -0.006"
      rpy="0 0 0" />
    <parent
      link="base_link" />
    <child
      link="wheel1" />
    <axis
      xyz="0 -1 0" />
  </joint>
  <link
    name="wheel2">
    <inertial>
      <origin
        xyz="0 -0.12 0"
        rpy="0 0 0" />
      <mass
        value="5" />
      <inertia
        ixx="0.13237"
        ixy="3.4868E-18"
        ixz="-9.1067E-19"
        iyy="0.13869"
        iyz="4.9054E-19"
        izz="0.13237" />
    </inertial>
    <visual>
      <origin
        xyz="0 0 0"
        rpy="0 0 0" />
      <geometry>
        <mesh
          filename="package://ca/meshes/wheel2.STL" />
      </geometry>
      <material
        name="">
        <color
          rgba="0.79216 0.81961 0.93333 1" />
      </material>
    </visual>
    <collision>
      <origin
        xyz="0 0 0"
        rpy="0 0 0" />
      <geometry>
        <mesh
          filename="package://ca/meshes/wheel2.STL" />
      </geometry>
    </collision>
  </link>
  <joint
    name="wheel2j"
    type="continuous">
    <origin
      xyz="0.695 -0.4065 -0.006"
      rpy="0 0 0" />
    <parent
      link="base_link" />
    <child
      link="wheel2" />
    <axis
      xyz="0 -1 0" />
  </joint>
  <link
    name="wheel3">
    <inertial>
      <origin
        xyz="0 0.12 0"
        rpy="0 0 0" />
      <mass
        value="5" />
      <inertia
        ixx="0.13237"
        ixy="1.7347E-18"
        ixz="-1.9437E-36"
        iyy="0.13869"
        iyz="2.808E-34"
        izz="0.13237" />
    </inertial>
    <visual>
      <origin
        xyz="0 0 0"
        rpy="0 0 0" />
      <geometry>
        <mesh
          filename="package://ca/meshes/wheel3.STL" />
      </geometry>
      <material
        name="">
        <color
          rgba="0.79216 0.81961 0.93333 1" />
      </material>
    </visual>
    <collision>
      <origin
        xyz="0 0 0"
        rpy="0 0 0" />
      <geometry>
        <mesh
          filename="package://ca/meshes/wheel3.STL" />
      </geometry>
    </collision>
  </link>
  <joint
    name="wheel3j"
    type="continuous">
    <origin
      xyz="-0.695 0.4065 -0.006"
      rpy="0 0 0" />
    <parent
      link="base_link" />
    <child
      link="wheel3" />
    <axis
      xyz="0 -1 0" />
  </joint>
  <link
    name="wheel4">
    <inertial>
      <origin
        xyz="0 -0.12 0"
        rpy="0 0 0" />
      <mass
        value="5" />
      <inertia
        ixx="0.13237"
        ixy="4.0407E-18"
        ixz="4.666E-20"
        iyy="0.13869"
        iyz="3.1414E-20"
        izz="0.13237" />
    </inertial>
    <visual>
      <origin
        xyz="0 0 0"
        rpy="0 0 0" />
      <geometry>
        <mesh
          filename="package://ca/meshes/wheel4.STL" />
      </geometry>
      <material
        name="">
        <color
          rgba="0.79216 0.81961 0.93333 1" />
      </material>
    </visual>
    <collision>
      <origin
        xyz="0 0 0"
        rpy="0 0 0" />
      <geometry>
        <mesh
          filename="package://ca/meshes/wheel4.STL" />
      </geometry>
    </collision>
  </link>
  <joint
    name="wheel4j"
    type="continuous">
    <origin
      xyz="-0.695 -0.4065 -0.006"
      rpy="0 0 0" />
    <parent
      link="base_link" />
    <child
      link="wheel4" />
    <axis
      xyz="0 -1 0" />
  </joint>
  <link
    name="lidar">
    <inertial>
      <origin
        xyz="0 0 0"
        rpy="0 0 0" />
      <mass
        value="0" />
      <inertia
        ixx="0"
        ixy="0"
        ixz="0"
        iyy="0"
        iyz="0"
        izz="0" />
    </inertial>
    <visual>
      <origin
        xyz="0 0 0"
        rpy="0 0 0" />
      <geometry>
        <mesh
          filename="package://ca/meshes/lidar.STL" />
      </geometry>
      <material
        name="">
        <color
          rgba="1 1 1 1" />
      </material>
    </visual>
    <collision>
      <origin
        xyz="0 0 0"
        rpy="0 0 0" />
      <geometry>
        <mesh
          filename="package://ca/meshes/lidar.STL" />
      </geometry>
    </collision>
  </link>
  <joint
    name="lidarj"
    type="fixed">
    <origin
      xyz="0.815 0.1 0.258"
      rpy="0 0 1.5708" />
    <parent
      link="base_link" />
    <child
      link="lidar" />
    <axis
      xyz="0 0 0" />
  </joint>
 <!-- hokuyo -->
  <gazebo reference="lidar">
    <sensor type="ray" name="head_hokuyo_sensor">
      <pose>0 0 0 0 0 0</pose>
      <visualize>true</visualize>
      <update_rate>40</update_rate>
      <ray>
        <scan>
          <horizontal>
            <samples>720</samples>
            <resolution>1</resolution>
            <min_angle>-2.5</min_angle>
            <max_angle>0.35</max_angle>
          </horizontal>
        </scan>
        <range>
          <min>0.10</min>
          <max>30.0</max>
          <resolution>0.01</resolution>
        </range>
        <noise>
          <type>gaussian</type>
          <!-- Noise parameters based on published spec for Hokuyo laser
               achieving "+-30mm" accuracy at range < 10m.  A mean of 0.0m and
               stddev of 0.01m will put 99.7% of samples within 0.03m of the true
               reading. -->
          <mean>0.0</mean>
          <stddev>0.01</stddev>
        </noise>
      </ray>
      <plugin name="gazebo_ros_head_hokuyo_controller" filename="libgazebo_ros_laser.so">
        <topicName>/scan</topicName>
        <frameName>lidar</frameName>
      </plugin>
    </sensor>
  </gazebo>

<gazebo>
  <plugin name="skid_steer_drive_controller" filename="libgazebo_ros_skid_steer_drive.so">
    <updateRate>100.0</updateRate>
    <robotNamespace>/</robotNamespace>
    <leftFrontJoint>wheel1j</leftFrontJoint>
    <rightFrontJoint>wheel2j</rightFrontJoint>
    <leftRearJoint>wheel3j</leftRearJoint>
    <rightRearJoint>wheel4j</rightRearJoint>
    <wheelSeparation>0.813</wheelSeparation>
    <wheelDiameter>0.280</wheelDiameter>
    <robotBaseFrame>base_link</robotBaseFrame>
    <odometryTopic>odom</odometryTopic>
    <odometryFrame>odom</odometryFrame>
    <torque>20</torque>
    <topicName>cmd_vel</topicName>
    <broadcastTF>true</broadcastTF>
    <publishTF>true</publishTF>
  </plugin>
</gazebo>
</robot>
